Workbook

Sheet TỔNG LƯƠNG
A1: BẢNG LƯƠNG BHVT - KỸ THUẬT VÀ KHO HCM - THÁNG 06
A2: STT | B2: Tên NV | C2: Chức vụ | D2: Lương và thời gian làm việc | H2: Phụ cấp | M2: Khấu trừ | P2: Thực lĩnh | Q2: TỔNG CHI
D3: Lương cơ bản | E3: Số công chuẩn | F3: Số công làm thực tế | G3: Lương thực nhận | H3: Doanh thu | I3: Tăng ca | J3: Xăng xe đi tỉnh | K3: Thưởng | L3: Phụ cấp thêm | M3: Tạm ứng | N3: Trừ khác | O3: BHXH
A4: 1 | B4: ĐỖ THỊ ANH THƯ | C4: Điều phối | D4: 0 | E4: 26 | F4: ='BẢNG CHẤM CÔNG'!AM7 -> 25 | G4: =(D4/E4)*F4 -> 0 | H4: =I15 -> 0 | J4: 0 | L4: 0 | M4: 0 | N4: 0 | O4: 0 | P4: =G4+(SUM(H4:L4))-(SUM(M4:O4)) -> 0 | Q4: =SUM(P4:P8) -> 0
A5: 2 | B5: ĐẶNG THÀNH ĐỨC | C5: Kho | D5: 0 | E5: 26 | F5: 26 | G5: =(D5/E5)*F5 -> 0 | H5: ='DOANH THU KỸ THUẬT'!J6 -> 0 | J5: 0 | L5: 0 | M5: 0 | N5: 0 | O5: 0 | P5: =G5+(SUM(H5:L5))-(SUM(M5:O5)) -> 0
A6: 3 | B6: VŨ VĂN GIANG | C6: Kỹ thuật | D6: 0 | E6: 26 | F6: ='BẢNG CHẤM CÔNG'!AM9 -> 21 | G6: =(D6/E6)*F6 -> 0 | H6: ='DOANH THU KỸ THUẬT'!J4 -> 0 | J6: 0 | L6: 0 | M6: 0 | N6: 0 | O6: 0 | P6: =G6+(SUM(H6:L6))-(SUM(M6:O6)) -> 0
A7: 4 | B7: LÂM ĐỨC KHẢI | C7: Kỹ thuật | D7: 0 | E7: 26 | F7: ='BẢNG CHẤM CÔNG'!AM10 -> 25 | G7: =(D7/E7)*F7 -> 0 | H7: ='DOANH THU KỸ THUẬT'!J5 -> 0 | J7: 0 | L7: 0 | M7: 0 | N7: 0 | O7: 0 | P7: =G7+(SUM(H7:L7))-(SUM(M7:O7)) -> 0
A8: 5 | B8: ĐẶNG HOÀNG THANH TRƯỜNG | C8: Kỹ thuật | D8: 0 | E8: 26 | F8: ='BẢNG CHẤM CÔNG'!AM11 -> 26 | G8: =(D8/E8)*F8 -> 0 | H8: ='DOANH THU KỸ THUẬT'!J7 -> 0 | J8: 0 | L8: 0 | M8: 0 | N8: 0 | O8: 0 | P8: =G8+(SUM(H8:L8))-(SUM(M8:O8)) -> 0
B11: Số tài khoản nhân viên | G11: DOANH THU THƯ
B12: Vũ Văn Giang | C12: 04001011962060 | D12: MSB | E12: CPQ | G12: DT HCM | H12: 0 | I12: 0
B13: Đặng Thành Đức | C13: 04301018913163 | D13: MSB | E13: CPQ | G13: DTDL | H13: 0 | I13: 0
B14: Lâm Đức Khải | C14: 1063596692 | D14: Vietcom | E14: MRVU
B15: Đỗ Thị Anh Thư | C15: 0261003469893 | D15: Vietcom | E15: MRVU | G15: Tổng cộng | I15: =SUM(I12:I14) -> 0
B16: Đặng Hoàng Thanh Trường | C16: 9776609382 | D16: Viecom | E16: MRVU

Sheet DOANH THU KỸ THUẬT
A1: DOANH THU LẮP CỦA KT HCM - 06/2026
A2: Nhân Viên | B2: Lắp quạt thường | C2: Lắp tỉnh/trần khó, cao | D2: Lắp quạt cây/quạt bàn | E2: Lắp quạt lớn (villa, xtreme,..) | F2: Spa quạt/Sơn quạt (Sơn bộ thân ốp hoặc nguyên chiếc) | G2: Giao hàng/Khảo sát/Sơn quạt (Sơn 3 cánh hoặc bộ ty ốp) | H2: Bảo hành/gia cố | I2: Xăng xe Đi xa Nội thành (Từ 13km) | J2: Lương doanh số
A3: Doanh thu | B3: 0 | C3: 0 | D3: 0 | E3: 0 | F3: 0 | G3: 0 | H3: 0 | I3: 0
A4: Vũ Văn Giang | B4: 1.5 | C4: 27 | G4: 3 | H4: 9 | I4: 8 | J4: =B4*B3+C4*C3+F4*F3+G4*G3+H4*H3+I4*I3+D4*D3 -> 0
A5: Lâm Đức Khải | B5: 8 | C5: 25 | D5: 1 | F5: 2 | G5: 6 | H5: 14 | I5: 6 | J5: =B5*B3+C5*C3+F5*F3+G5*G3+H5*H3+I5*I3+D5*D3 -> 0
A6: Đặng Thành Đức | B6: 8 | C6: 22.5 | F6: 1 | G6: 13 | H6: 23 | I6: 10 | J6: =(B6*B3)+(C6*C3)+(F6*F3)+(G6*G3)+(H6*H3)+(I6*I3)+D6*D3 -> 0
A7: Đặng Hoàng Thanh Trường | B7: 10.5 | C7: 28.5 | F7: 4 | G7: 8 | H7: 10 | I7: 9 | J7: =B7*B3+C7*C3+D7*D3+E7*E3+F7*F3+G7*G3+H7*H3+I7*I3 -> 0
A9: Nhân Viên (Chỉ áp dụng cho KT tự đi xe máy) | B9: Long An gần, BD, BH,C Chi <50km | D9: Đồng Nai, Long an xa, Tiền Giang, BDuong Xa 50km -> 70km | F9: Đồng Nai, Tây Ninh,.. > 70-100km | H9: Bình Phước, BRVT,.. > 100km | J9: TỔNG CỘNG | K9: Diễn giải
A10: Doanh thu | B10: 0 | D10: 1 | F10: 2 | H10: 3
A11: Vũ Văn Giang | B11: 1 | J11: =B11*B10+F11*F10+D11*D10 -> 0 | K11: 11/6 biên hòa
A12: Đặng Thành Đức | B12: 1 | J12: =B12*B10 -> 0 | K12: 16/6 bình dương
A13: Lâm Đức Khải | B13: 2 | J13: =B13*B10+D13*D10+F13*F10 -> 0 | K13: 2/6 Biên hòa 27/6 Long an
A14: Đặng Hoàng Thanh Trường | B14: 1 | J14: =B14*B10 -> 0 | K14: 29/7 biên hòa

Sheet BẢNG CHẤM CÔNG
A1: BẢNG CHẤM CÔNG
A2: THÁNG | R2: 6 | T2: Số công trong tháng làm đủ: | Z2: 26
A3: NĂM | R3: 2026
A4: STT | B4: HỌ VÀ TÊN | C4: CHỨC VỤ | D4: NGÀY TRONG THÁNG | AI4: TÍNH NGÀY CÔNG
D5: =DATE($R$3,$R$2,1) -> 46174 | E5: =IFERROR(IF(D5+1>EOMONTH(D5,0),"",D5+1),"") -> 46175 | F5: =IFERROR(IF(E5+1>EOMONTH(E5,0),"",E5+1),"") -> 46176 | G5: =IFERROR(IF(F5+1>EOMONTH(F5,0),"",F5+1),"") -> 46177 | H5: =IFERROR(IF(G5+1>EOMONTH(G5,0),"",G5+1),"") -> 46178 | I5: =IFERROR(IF(H5+1>EOMONTH(H5,0),"",H5+1),"") -> 46179 | J5: =IFERROR(IF(I5+1>EOMONTH(I5,0),"",I5+1),"") -> 46180 | K5: =IFERROR(IF(J5+1>EOMONTH(J5,0),"",J5+1),"") -> 46181 | L5: =IFERROR(IF(K5+1>EOMONTH(K5,0),"",K5+1),"") -> 46182 | ... AH5: =IFERROR(IF(AG5+1>EOMONTH(AG5,0),"",AG5+1),"") | AI5: Làm nguyên ngày | AJ5: Làm nửa ngày | AK5: Ngày nghỉ hưởng lương | AL5: Ngày nghỉ ko lương | AM5: TỔNG NGÀY CÔNG | AN5: GHI CHÚ
D6: =TEXT(D5,"[$-42a]ddd") -> T2 | E6: =TEXT(E5,"[$-42a]ddd") -> T3 | F6: =TEXT(F5,"[$-42a]ddd") -> T4 | G6: =TEXT(G5,"[$-42a]ddd") -> T5 | H6: =TEXT(H5,"[$-42a]ddd") -> T6 | I6: =TEXT(I5,"[$-42a]ddd") -> T7 | J6: =TEXT(J5,"[$-42a]ddd") -> CN | K6: =TEXT(K5,"[$-42a]ddd") -> T2 | ... AH6: =TEXT(AH5,"[$-42a]ddd")
A7: 1 | B7: ĐỖ THỊ ANH THƯ | C7: Điều phối | D7: X | E7: X | F7: X | G7: X | H7: X | I7: X | J7: K | K7: X | L7: X | M7: X | N7: X | O7: X | P7: X | Q7: X | R7: X | S7: X | T7: X | U7: X | V7: X | W7: X | X7: K | Y7: X | Z7: X | AA7: X | AB7: X | AC7: K | AD7: K | AE7: K | AF7: X | AG7: X | AI7: =COUNTIF(D7:AH7,"X") -> 25 | AJ7: =COUNTIF(D7:AH7,"N") -> 0 | AK7: =COUNTIF(D7:AH7,"L") -> 0 | AL7: =COUNTIF(D7:AH7,"K") -> 5 | AM7: =AI7+(AJ7/2)+AK7 -> 25
A8: 2 | B8: ĐẶNG THÀNH ĐỨC | C8: Kho | D8: X | E8: X | F8: X | G8: X | H8: X | I8: X | J8: K | K8: X | L8: X | M8: X | N8: X | O8: X | P8: X | Q8: K | R8: X | S8: X | T8: X | U8: X | V8: X | W8: X | X8: K | Y8: X | Z8: X | AA8: X | AB8: X | AC8: X | AD8: X | AE8: K | AF8: X | AG8: X | AI8: =COUNTIF(D8:AH8,"X") -> 26 | AJ8: =COUNTIF(D8:AH8,"N") -> 0 | AK8: =COUNTIF(D8:AH8,"L") -> 0 | AL8: =COUNTIF(D8:AH8,"K") -> 4 | AM8: =AI8+(AJ8/2)+AK8 -> 26 | AN8: thiếu a đức 1 off bù lắp kosmo về tối
A9: 3 | B9: VŨ VĂN GIANG | C9: Kỹ thuật | D9: X | E9: X | F9: X | G9: X | H9: X | I9: X | J9: K | K9: X | L9: X | M9: X | N9: X | O9: X | P9: X | Q9: K | R9: X | S9: X | T9: X | U9: X | V9: X | W9: X | X9: K | Y9: X | Z9: X | AA9: X | AB9: K | AC9: K | AD9: K | AE9: K | AF9: K | AG9: K | AI9: =COUNTIF(D9:AH9,"X") -> 21 | AJ9: =COUNTIF(D9:AH9,"N") -> 0 | AK9: =COUNTIF(D9:AH9,"L") -> 0 | AL9: =COUNTIF(D9:AH9,"K") -> 9 | AM9: =AI9+(AJ9/2)+AK9 -> 21
A10: 4 | B10: LÂM ĐỨC KHẢI | C10: Kỹ thuật | D10: X | E10: X | F10: X | G10: X | H10: X | I10: X | J10: K | K10: X | L10: X | M10: X | N10: X | O10: X | P10: X | Q10: K | R10: X | S10: X | T10: X | U10: X | V10: X | W10: X | X10: K | Y10: X | Z10: X | AA10: X | AB10: X | AC10: X | AD10: X | AE10: K | AF10: K | AG10: X | AI10: =COUNTIF(D10:AH10,"X") -> 25 | AJ10: =COUNTIF(D10:AH10,"N") -> 0 | AK10: =COUNTIF(D10:AH10,"L") -> 0 | AL10: =COUNTIF(D10:AH10,"K") -> 5 | AM10: =AI10+(AJ10/2)+AK10 -> 25
A11: 5 | B11: ĐẶNG HOÀNG THANH TRƯỜNG | C11: Kỹ thuật | D11: X | E11: X | F11: X | G11: X | H11: X | I11: X | J11: K | K11: X | L11: X | M11: X | N11: X | O11: X | P11: X | Q11: K | R11: X | S11: X | T11: X | U11: X | V11: X | W11: X | X11: K | Y11: X | Z11: X | AA11: X | AB11: X | AC11: X | AD11: X | AE11: K | AF11: X | AG11: X | AI11: =COUNTIF(D11:AH11,"X") -> 26 | AJ11: =COUNTIF(D11:AH11,"N") -> 0 | AK11: =COUNTIF(D11:AH11,"L") -> 0 | AL11: =COUNTIF(D11:AH11,"K") -> 4 | AM11: =AI11+(AJ11/2)+AK11 -> 26
B12: Ghi chú:
B13: Hành chính 8h-17h30 | C13: X | I13: TĂNG CA
B14: Làn nửa ngày | C14: N
B15: Ngày nghỉ hưởng lương | C15: L
B16: Ngày nghỉ ko lương | C16: K
I18: Lương tăng ca: x1.5 ngoài giờ
I19: Vũ Văn Giang
I20: Đặng Thành Đức | O20: =((9000000/Z2)/8)*N20*1.5 -> 0
I21: Lâm Đức Khải | O21: =((6500000/26)/8)*N21*1.5 -> 0
I22: Đặng Hoàng Thanh Trường | O22: =((7000000/26)/8)*N22*1.5 -> 0
I23: Đỗ Thị Anh Thư

Sheet DT ĐẠI LÝ
A1: DOANH THU ĐẠI LÝ THÁNG 4-5-6
A2: STT | B2: ĐẠI LÝ | C2: HÓA ĐƠN | D2: NGÀY BÁN | E2: MÃ SP | F2: SL | G2: ĐƠN NIÊM YẾT | H2: MỨC CK | I2: ĐƠN SAU CK | J2: THỰC THU | K2: GHI CHÚ
A3: 1 | B3: Đại lý Nam Dương Thịnh (Quatgio.vn) - HCM | C3: HD040181 | D3: 46116 | E3: Mega 96 | F3: 4 | G3: 0 | H3: 0 | I3: =G3-(G3*H3) -> 0 | J3: 0 | K3: blank
A4: 2 | C4: HD040184 | D4: 46116 | E4: Bộ điều khiển Indus 2m | F4: 1 | G4: 0 | H4: 0 | I4: =G4-H4 -> 0 | J4: 0 | K4: blank
A5: 3 | C5: HD040233 | D5: 46121 | E5: Mega pro 8 cánh | F5: 1 | G5: 0 | H5: 0 | I5: =G5-(G5*H5) -> 0 | J5: 0 | K5: blank
A6: 4 | C6: HD008770 | D6: 46184 | E6: Tín hiệu mega 96 | F6: 1 | G6: 0 | H6: 0 | I6: =G6-(G6*H6) -> 0 | J6: 0 | K6: blank
A7: 5 | B7: ĐL Thiết Bị Điện Nam Phát B.Chánh - Anh Nam | C7: HD040195 | D7: 46118 | E7: Rose | F7: 1 | G7: 0 | H7: 0 | I7: =G7-(G7*H7) -> 0 | J7: 0 | K7: blank
A8: 6 | C8: HD040370 | D8: 46134 | E8: Thin 56 nâu | F8: 1 | G8: 0 | H8: 0 | I8: =G8-(G8*H8) -> 0 | J8: 0 | K8: blank
A9: 7 | C9: HD008799 | D9: 46186 | E9: Lotus NL | F9: 1 | G9: 0 | H9: 0 | I9: =G9-(G9*H9) -> 0 | J9: 0 | K9: blank
A10: 8 | B10: ĐL Hưng Thịnh Phát - chị Ngô Nụ | C10: HD040322 | D10: 46130 | E10: Thin 40 nâu | F10: 1 | G10: 0 | H10: 0 | I10: =G10-(G10*H10) -> 0 | J10: 0 | K10: blank
A11: 9 | C11: HD008837 | D11: 46190 | E11: Strong wn | F11: 1 | G11: 0 | H11: 0 | I11: =G11-(G11*H11) -> 0 | J11: 0 | K11: blank
A12: 10 | B12: Cty CP Thái An Ecolife | C12: HD040329 | D12: 46130 | E12: 1 lotus 5L 1 lotus NL | F12: 2 | G12: 0 | H12: 0 | I12: =G12-(G12*H12) -> 0 | J12: 0 | K12: blank
A13: 11 | C13: TT022654 | D13: 46135 | E13: Thanh toán tiền mặt | I13: =G13-(G13*H13) -> 0 | J13: 0 | K13: blank
A14: 12 | C14: TT022691 | D14: 46147 | E14: Thanh toán công nợ | I14: =G14-(G14*H14) -> 0 | J14: 0 | K14: blank
A15: 13 | C15: TT022692 | D15: 46147 | E15: Thanh toán tiền mặt | I15: =G15-(G15*H15) -> 0 | J15: 0 | K15: blank
A16: 14 | C16: HD040529 | D16: 46157 | E16: Lotus NL | F16: 2 | G16: 0 | H16: 0 | I16: =G16-(G16*H16) -> 0 | K16: blank
A17: 15 | C17: HD040544 | D17: 46158 | E17: Slice xám | F17: 1 | G17: 0 | H17: 0 | I17: =G17-(G17*H17) -> 0 | K17: blank
A18: 16 | E18: công lắp | F18: 1 | G18: 0 | H18: 0 | I18: =G18-(G18*H18) -> 0 | K18: blank
A19: 17 | C19: HD040670 | D19: 46169 | E19: Slice xám | F19: 1 | G19: 0 | H19: 0 | I19: =G19-(G19*H19) -> 0 | J19: 0 | K19: blank
A20: 18 | C20: TT022861 | D20: 46189 | E20: Thanh toán công nợ | I20: =G20-(G20*H20) -> 0 | J20: 0 | K20: blank
A21: 19 | C21: TT022862 | D21: 46189 | E21: Thanh toán tiền mặt | I21: =G21-(G21*H21) -> 0 | J21: 0 | K21: blank
A22: 20 | B22: ĐL Đèn Trang Trí 298 Vũng Tàu - Chị Trang | C22: HD040392 | D22: 46138 | E22: Halo đen | F22: 4 | G22: 0 | H22: 0 | I22: =(G22-(G22*H22))*F22 -> 0 | J22: 0 | K22: blank
A23: 21 | B23: Đại lý Nguyễn Giang- 67A Yersin HCM | C23: HD040528 | D23: 46157 | E23: Candy MP | F23: 2 | G23: 0 | H23: 0 | I23: =G23-(G23*H23) -> 0 | J23: 0 | K23: blank
A24: 22 | B24: Đại Lý Thiên Đường Ánh Sáng - Chị Nhung | C24: HD008893 | D24: 46195 | E24: đổi bộ dk8 > tín hiệu lotus DC | F24: 1 | G24: 0 | H24: 0 | I24: =G24-(G24*H24) -> 0 | J24: 0 | K24: blank
A25: 23 | B25: Đèn trang trí Thắng Thịnh Phát - Anh Thắng | C25: HD008836 | D25: 46190 | E25: Strong Gold | F25: 1 | G25: 0 | H25: 0 | I25: =G25-(G25*H25) -> 0 | J25: 0 | K25: blank
A26: 24 | B26: Anh Cao Tiến Dũng - Thương Mại | C26: HD008826 | D26: 46189 | E26: Điều khiển AC 8 Speed | F26: 1 | G26: 0 | H26: 0 | I26: =G26-(G26*H26) -> 0 | J26: 0 | K26: blank
B27: TỔNG CỘNG | J27: =SUM(J3:J26) -> 0 | K27: blank
B28: DOANH THU DL | J28: =J27*0.5% -> 0 | K28: blank

Sheet PHIẾU LƯƠNG
B1: PHIẾU CHI LƯƠNG
B3: PHIẾU LƯƠNG THÁNG 06.2026 | D3: ĐỖ THỊ ANH THƯ | G3: PHIẾU LƯƠNG THÁNG 06.2026 | I3: ĐẶNG THÀNH ĐỨC
B4: Năm bắt đầu làm | C4: Tháng 3.2018 | D4: Khu vực | E4: HCM | G4: Năm bắt đầu làm | H4: Tháng 6.2016 | I4: Khu vực | J4: HCM
B5: Bộ phận | C5: Điều phối | D5: Lương cơ bản | E5: ='TỔNG LƯƠNG'!D4 -> 0 | G5: Bộ phận | H5: Kho | I5: Lương cơ bản | J5: ='TỔNG LƯƠNG'!D5 -> 0
B6: Diễn giải | C6: Ngày công | D6: Thành tiền | E6: Ghi Chú | G6: Diễn giải | H6: Ngày công | I6: Thành tiền | J6: Ghi Chú
B7: Lương thực tế | C7: ='TỔNG LƯƠNG'!F4 -> 25 | D7: ='TỔNG LƯƠNG'!G4 -> 0 | G7: Lương thực tế | H7: ='TỔNG LƯƠNG'!F5 -> 26 | I7: ='TỔNG LƯƠNG'!G5 -> 0
B8: Tăng ca x1.5 | G8: Tăng ca x1.5
B9: Tăng ca x2.0 | G9: Tăng ca x2.0
B10: Phụ cấp | D10: ='TỔNG LƯƠNG'!L4 -> 0 | G10: Phụ cấp | I10: ='TỔNG LƯƠNG'!L5 -> 0 | J10: làm điện lắp Giant (8chiec)
B11: Tăng ca | D11: ='TỔNG LƯƠNG'!I4 -> 0 | G11: Tăng ca | I11: ='TỔNG LƯƠNG'!I5 -> 0
B12: Thưởng doanh số | D12: ='TỔNG LƯƠNG'!H4 -> 0 | G12: Thưởng doanh số | I12: ='TỔNG LƯƠNG'!H5 -> 0
B13: Xăng xe | D13: =0 -> 0 | G13: Xăng xe | I13: ='DOANH THU KỸ THUẬT'!J12 -> 0
B14: Tổng lương (1) | D14: =SUM(D7:D13) -> 0 | G14: Tổng lương (1) | I14: =SUM(I7:I13) -> 0
B15: BHXH | D15: 0 | G15: BHXH | I15: 0
B16: Tạm ứng | G16: Tạm ứng
B17: Quỹ công đoàn | D17: 0 | G17: Quỹ công đoàn | I17: 0
B18: Trừ khác | D18: 0 | G18: Trừ khác | I18: 0
B19: Tổng khấu trừ (2) | D19: =SUM(D15:D18) -> 0 | G19: Tổng khấu trừ (2) | I19: =SUM(I15:I18) -> 0
B20: Thực lĩnh (=1-2) | D20: =D14-D19 -> 0 | G20: Thực lĩnh (=1-2) | I20: =I14-I19 -> 0
B21: MR*VU chân thành cảm ơn sự đóng góp của các bạn ! | G21: MR*VU chân thành cảm ơn sự đóng góp của các bạn !
B24: PHIẾU LƯƠNG THÁNG 06.2026 | D24: VŨ VĂN GIANG | G24: PHIẾU LƯƠNG THÁNG 06.2026 | I24: LÂM ĐỨC KHẢI
B25: Năm bắt đầu làm | C25: Tháng 4.2019 | D25: Khu vực | E25: HCM | G25: Năm bắt đầu làm | H25: Tháng 4.2023 | I25: Khu vực | J25: HCM
B26: Bộ phận | C26: Kỹ thuật | D26: Lương cơ bản | E26: ='TỔNG LƯƠNG'!D6 -> 0 | G26: Bộ phận | H26: Kỹ thuật | I26: Lương cơ bản | J26: ='TỔNG LƯƠNG'!D7 -> 0
B27: Diễn giải | C27: Ngày công | D27: Thành tiền | E27: Ghi Chú | G27: Diễn giải | H27: Ngày công | I27: Thành tiền | J27: Ghi Chú
B28: Lương thực tế | C28: ='TỔNG LƯƠNG'!F6 -> 21 | D28: ='TỔNG LƯƠNG'!G6 -> 0 | G28: Lương thực tế | H28: ='TỔNG LƯƠNG'!F7 -> 25 | I28: ='TỔNG LƯƠNG'!G7 -> 0
B29: Tăng ca x1.5 | G29: Tăng ca x1.5
B30: Tăng ca x2.0 | G30: Tăng ca x2.0
B31: Phụ cấp | D31: ='TỔNG LƯƠNG'!L6 -> 0 | E31: kéo thêm đoạn điện về tụ | G31: Phụ cấp | I31: ='TỔNG LƯƠNG'!L7 -> 0 | J31: kéo thêm đoạn điện về tụ
B32: Tăng ca | D32: ='TỔNG LƯƠNG'!I6 -> 0 | G32: Tăng ca | I32: ='TỔNG LƯƠNG'!I7 -> 0
B33: Thưởng doanh số | D33: ='TỔNG LƯƠNG'!H6 -> 0 | G33: Thưởng doanh số | I33: ='TỔNG LƯƠNG'!H7 -> 0
B34: Xăng xe | D34: ='TỔNG LƯƠNG'!J6 -> 0 | G34: Xăng xe | I34: ='TỔNG LƯƠNG'!J7 -> 0
B35: Tổng lương (1) | D35: =SUM(D28:D34) -> 0 | G35: Tổng lương (1) | I35: =SUM(I28:I34) -> 0
B36: BHXH | D36: 0 | E36: Công ty Đóng | G36: BHXH | I36: 0
B37: Tạm ứng | D37: ='TỔNG LƯƠNG'!M6 -> 0 | G37: Tạm ứng | I37: 0
B38: Quỹ công đoàn | D38: 0 | G38: Quỹ công đoàn | I38: 0
B39: Trừ khác | D39: 0 | G39: Trừ khác | I39: 0
B40: Tổng khấu trừ (2) | D40: =SUM(D36:D39) -> 0 | G40: Tổng khấu trừ (2) | I40: =SUM(I36:I39) -> 0
B41: Thực lĩnh (=1-2) | D41: =D35-D40 -> 0 | G41: Thực lĩnh (=1-2) | I41: =I35-I40 -> 0
B42: MR*VU chân thành cảm ơn sự đóng góp của các bạn ! | G42: MR*VU chân thành cảm ơn sự đóng góp của các bạn !
B44: PHIẾU LƯƠNG THÁNG 06.2026 | D44: ĐẶNG HOÀNG THANH TRƯỜNG
...
